Workbook

Sheet requestors pivot
A2: Requestor_ID | E2: Email | F2: first_name | G2: last_name | H2: Phone | I2: City | J2: State | K2: Credits | L2: code_generated_when | M2: Admin | N2: Creation_date | O2: Last_mod_date | P2: last_failed_login
A3: Row Labels | B3: Max of P-Days | C3: Min of P-Days
A4: 1962792 | B4: 2 | C4: 2 | E4: =LOOKUP($A4,original!$AE:$AE,original!H:H) -> sam.hoffman99@gmail.com | F4: =LOOKUP($A4,original!$AE:$AE,original!A:A) -> Sam | G4: =LOOKUP($A4,original!$AE:$AE,original!B:B) -> Hoffman | H4: =LOOKUP($A4,original!$AE:$AE,original!G:G) -> 720-810-5776 | I4: =IF(LOOKUP($A4,original!$AE:$AE,original!D:D)=0,"",LOOKUP($A4,original!$AE:$AE,original!D:D)) -> Oakland | J4: =IF(LOOKUP($A4,original!$AE:$AE,original!E:E)=0,"",LOOKUP($A4,original!$AE:$AE,original!E:E)) -> CA | K4: =LOOKUP($A4,original!$AE:$AE,original!M:M) -> 2 | M4: FALSE
A5: 1969495 | B5: 2 | C5: 2 | E5: =LOOKUP($A5,original!$AE:$AE,original!H:H) -> ben.spielman1223@gmail.com | F5: =LOOKUP($A5,original!$AE:$AE,original!A:A) -> Benjamin | G5: =LOOKUP($A5,original!$AE:$AE,original!B:B) -> Spielman | H5: =LOOKUP($A5,original!$AE:$AE,original!G:G) -> 301-830-0735 | I5: =IF(LOOKUP($A5,original!$AE:$AE,original!D:D)=0,"",LOOKUP($A5,original!$AE:$AE,original!D:D)) -> San Francisco | J5: =IF(LOOKUP($A5,original!$AE:$AE,original!E:E)=0,"",LOOKUP($A5,original!$AE:$AE,original!E:E)) -> CA | K5: =LOOKUP($A5,original!$AE:$AE,original!M:M) -> 2 | M5: FALSE
A6: 1975905 | B6: 2 | C6: 2 | E6: =LOOKUP($A6,original!$AE:$AE,original!H:H) -> leo.stanislas@gmail.com | F6: =LOOKUP($A6,original!$AE:$AE,original!A:A) -> Leo | G6: =LOOKUP($A6,original!$AE:$AE,original!B:B) -> Stanislaus | H6: =LOOKUP($A6,original!$AE:$AE,original!G:G) -> 818-930-2028 | I6: =IF(LOOKUP($A6,original!$AE:$AE,original!D:D)=0,"",LOOKUP($A6,original!$AE:$AE,original!D:D)) -> South Lake Tahoe | J6: =IF(LOOKUP($A6,original!$AE:$AE,original!E:E)=0,"",LOOKUP($A6,original!$AE:$AE,original!E:E)) -> CA | K6: =LOOKUP($A6,original!$AE:$AE,original!M:M) -> 2 | M6: FALSE
A7: 2009181 | B7: 14 | C7: 14 | E7: =LOOKUP($A7,original!$AE:$AE,original!H:H) -> hut.coord@yahoo.com | F7: =LOOKUP($A7,original!$AE:$AE,original!A:A) -> Dick | G7: =LOOKUP($A7,original!$AE:$AE,original!B:B) -> Simpson | H7: =LOOKUP($A7,original!$AE:$AE,original!G:G) -> 650-494-9272 | I7: =IF(LOOKUP($A7,original!$AE:$AE,original!D:D)=0,"",LOOKUP($A7,original!$AE:$AE,original!D:D)) -> Palo Alto | J7: =IF(LOOKUP($A7,original!$AE:$AE,original!E:E)=0,"",LOOKUP($A7,original!$AE:$AE,original!E:E)) -> CA | K7: =LOOKUP($A7,original!$AE:$AE,original!M:M) -> 14 | M7: TRUE
A8: 3147593 | B8: 2 | C8: 2 | E8: =LOOKUP($A8,original!$AE:$AE,original!H:H) -> tk6174@gmail.com | F8: =LOOKUP($A8,original!$AE:$AE,original!A:A) -> Teddy | G8: =LOOKUP($A8,original!$AE:$AE,original!B:B) -> Koerner | H8: =LOOKUP($A8,original!$AE:$AE,original!G:G) -> 303-956-0501 | I8: =IF(LOOKUP($A8,original!$AE:$AE,original!D:D)=0,"",LOOKUP($A8,original!$AE:$AE,original!D:D)) -> San Francisco | J8: =IF(LOOKUP($A8,original!$AE:$AE,original!E:E)=0,"",LOOKUP($A8,original!$AE:$AE,original!E:E)) -> CA | K8: =LOOKUP($A8,original!$AE:$AE,original!M:M) -> 2 | M8: FALSE
A9: 3486858 | B9: 4 | C9: 4 | E9: =LOOKUP($A9,original!$AE:$AE,original!H:H) -> elk1234567@yahoo.com | F9: =LOOKUP($A9,original!$AE:$AE,original!A:A) -> Ethan | G9: =LOOKUP($A9,original!$AE:$AE,original!B:B) -> Kennon | H9: =LOOKUP($A9,original!$AE:$AE,original!G:G) -> 707-315-9872 | I9: =IF(LOOKUP($A9,original!$AE:$AE,original!D:D)=0,"",LOOKUP($A9,original!$AE:$AE,original!D:D)) -> San Francisco | J9: =IF(LOOKUP($A9,original!$AE:$AE,original!E:E)=0,"",LOOKUP($A9,original!$AE:$AE,original!E:E)) -> CA | K9: =LOOKUP($A9,original!$AE:$AE,original!M:M) -> 4 | M9: FALSE
A10: 7212312 | B10: 2 | C10: 2 | E10: =LOOKUP($A10,original!$AE:$AE,original!H:H) -> st1993@gmail.com | F10: =LOOKUP($A10,original!$AE:$AE,original!A:A) -> Scott | G10: =LOOKUP($A10,original!$AE:$AE,original!B:B) -> Bennett | H10: =LOOKUP($A10,original!$AE:$AE,original!G:G) -> 650-283-9916 | I10: =IF(LOOKUP($A10,original!$AE:$AE,original!D:D)=0,"",LOOKUP($A10,original!$AE:$AE,original!D:D)) -> San Francisco | J10: =IF(LOOKUP($A10,original!$AE:$AE,original!E:E)=0,"",LOOKUP($A10,original!$AE:$AE,original!E:E)) -> CA | K10: =LOOKUP($A10,original!$AE:$AE,original!M:M) -> 2 | M10: FALSE
A11: 27044381 | B11: 2 | C11: 2 | E11: =LOOKUP($A11,original!$AE:$AE,original!H:H) -> hal_tompkins@yahoo.com | F11: =LOOKUP($A11,original!$AE:$AE,original!A:A) -> Hal | G11: =LOOKUP($A11,original!$AE:$AE,original!B:B) -> Tompkins | H11: =LOOKUP($A11,original!$AE:$AE,original!G:G) -> 650-400-8351 | I11: =IF(LOOKUP($A11,original!$AE:$AE,original!D:D)=0,"",LOOKUP($A11,original!$AE:$AE,original!D:D)) -> Redwood City | J11: =IF(LOOKUP($A11,original!$AE:$AE,original!E:E)=0,"",LOOKUP($A11,original!$AE:$AE,original!E:E)) -> CA | K11: =LOOKUP($A11,original!$AE:$AE,original!M:M) -> 2 | M11: FALSE
A12: 28075512 | B12: 2 | C12: 2 | E12: =LOOKUP($A12,original!$AE:$AE,original!H:H) -> sjmac650@gmail.com | F12: =LOOKUP($A12,original!$AE:$AE,original!A:A) -> Sarah | G12: =LOOKUP($A12,original!$AE:$AE,original!B:B) -> MacPherson | H12: =LOOKUP($A12,original!$AE:$AE,original!G:G) -> 650-334-1015 | I12: =IF(LOOKUP($A12,original!$AE:$AE,original!D:D)=0,"",LOOKUP($A12,original!$AE:$AE,original!D:D)) -> San Francisco | J12: =IF(LOOKUP($A12,original!$AE:$AE,original!E:E)=0,"",LOOKUP($A12,original!$AE:$AE,original!E:E)) -> CA | K12: =LOOKUP($A12,original!$AE:$AE,original!M:M) -> 2 | M12: FALSE
A13: 28075894 | B13: 2 | C13: 2 | E13: =LOOKUP($A13,original!$AE:$AE,original!H:H) -> aomalley17@gmail.com | F13: =LOOKUP($A13,original!$AE:$AE,original!A:A) -> Anna | G13: =LOOKUP($A13,original!$AE:$AE,original!B:B) -> O'Malley | H13: =LOOKUP($A13,original!$AE:$AE,original!G:G) -> 802-540-5101 | I13: =IF(LOOKUP($A13,original!$AE:$AE,original!D:D)=0,"",LOOKUP($A13,original!$AE:$AE,original!D:D)) -> San Francisco | J13: =IF(LOOKUP($A13,original!$AE:$AE,original!E:E)=0,"",LOOKUP($A13,original!$AE:$AE,original!E:E)) -> CA | K13: =LOOKUP($A13,original!$AE:$AE,original!M:M) -> 2 | M13: FALSE
A14: 28090137 | B14: 2 | C14: 2 | E14: =LOOKUP($A14,original!$AE:$AE,original!H:H) -> d1passmore@yahoo.com | F14: =LOOKUP($A14,original!$AE:$AE,original!A:A) -> David | G14: =LOOKUP($A14,original!$AE:$AE,original!B:B) -> Passmore | H14: =LOOKUP($A14,original!$AE:$AE,original!G:G) -> 650-215-0374 | I14: =IF(LOOKUP($A14,original!$AE:$AE,original!D:D)=0,"",LOOKUP($A14,original!$AE:$AE,original!D:D)) -> San Francisco | J14: =IF(LOOKUP($A14,original!$AE:$AE,original!E:E)=0,"",LOOKUP($A14,original!$AE:$AE,original!E:E)) -> CA | K14: =LOOKUP($A14,original!$AE:$AE,original!M:M) -> 2 | M14: FALSE
A15: 28106784 | B15: 2 | C15: 2 | E15: =LOOKUP($A15,original!$AE:$AE,original!H:H) -> karadu422@gmail.com | F15: =LOOKUP($A15,original!$AE:$AE,original!A:A) -> Kate | G15: =LOOKUP($A15,original!$AE:$AE,original!B:B) -> Radu | H15: =LOOKUP($A15,original!$AE:$AE,original!G:G) -> 214-402-3918 | I15: =IF(LOOKUP($A15,original!$AE:$AE,original!D:D)=0,"",LOOKUP($A15,original!$AE:$AE,original!D:D)) -> Redwood City | J15: =IF(LOOKUP($A15,original!$AE:$AE,original!E:E)=0,"",LOOKUP($A15,original!$AE:$AE,original!E:E)) -> CA | K15: =LOOKUP($A15,original!$AE:$AE,original!M:M) -> 2 | M15: FALSE
... A86: 40395911 | B86: 2 | C86: 2 | E86: =LOOKUP($A86,original!$AE:$AE,original!H:H) -> roryoneill6@gmail.com | F86: =LOOKUP($A86,original!$AE:$AE,original!A:A) -> Rory | G86: =LOOKUP($A86,original!$AE:$AE,original!B:B) -> O'Neill | H86: =LOOKUP($A86,original!$AE:$AE,original!G:G) -> 240-705-4959 | I86: =IF(LOOKUP($A86,original!$AE:$AE,original!D:D)=0,"",LOOKUP($A86,original!$AE:$AE,original!D:D)) -> Oakland | J86: =IF(LOOKUP($A86,original!$AE:$AE,original!E:E)=0,"",LOOKUP($A86,original!$AE:$AE,original!E:E)) -> CA | K86: =LOOKUP($A86,original!$AE:$AE,original!M:M) -> 2 | M86: FALSE
A87: #VALUE!
A88: (blank)
A89: Grand Total | B89: 14 | C89: 1

Sheet original
A1: First Name | B1: Last Name | C1: Address | D1: City | E1: ST | F1: ZIP | G1: Phone | H1: E-Mail | I1: Hut | J1: Start | K1: Days | L1: #People | M1: P-Days | N1: Notes | O1: Ldr | P1: Special | Q1: Received | R1: Pref | S1: Hut | T1: YYi | U1: MMi | V1: DDi | W1: YYo | X1: MMo | Y1: DDo | Z1: Nights | AA1: Spaces | AB1: Flex? | AC1: Alloc? | AD1: Round2 | AE1: Requestor_ID | AF1: Benson | AG1: Bradley | AH1: Grubb | AI1: Ludlow | AJ1: Arrival | AK1: Departure | AL1: Choice_Number | AM1: Spots_ideal | AN1: Spots_min | AO1: Hut_granted | AP1: Spots_granted | AQ1: Status | AR1: Confirmed_How | AS1: Creation_date | AT1: Last_mod_date
A2: Sam | B2: Hoffman | D2: Oakland | E2: CA | G2: 720-810-5776 | H2: sam.hoffman99@gmail.com | I2: PGH | J2: 2025/07/19 | K2: 2 | L2: 1 | M2: =K2*L2 -> 2 | Q2: 251030t215200 | R2: 1 | S2: BEN | T2: 26 | U2: 2 | V2: 7 | W2: 26 | X2: 2 | Y2: 8 | Z2: =1000*(W2-T2)+100*(X2-U2)+(Y2-V2) -> 1 | AA2: 9 | AB2: HD | AC2: Y | AE2: =(CODE(MID(H2,1,1))-43)+(CODE(MID(H2,2,1))-43)*80+(CODE(MID(H2,3,1))-43)*80*80+(CODE(MID(H2,4,1))-43)*80*80*80 -> 1962792 | AF2: =OR($S2="BEN",NOT(ISERROR(SEARCH("H",$AB2)))) -> TRUE | AG2: =OR($S2="BRA",NOT(ISERROR(SEARCH("H",$AB2)))) -> TRUE | AH2: =OR($S2="PGH",NOT(ISERROR(SEARCH("H",$AB2)))) -> TRUE | AI2: =OR($S2="LUD",NOT(ISERROR(SEARCH("H",$AB2)))) -> TRUE | AJ2: =DATE(T2+2000,U2,V2) -> 44598 | AK2: =DATE(2000+W2,X2,Y2) -> 44599 | AL2: =VALUE(RIGHT(R2,1)) -> 1 | AM2: =AA2 -> 9 | AN2: =IF(ISERROR(SEARCH("N",$AB2)),AM2,MAX(AM2-4,4)) -> 9
A3: Benjamin | B3: Spielman | C3: 451 30th Ave | D3: San Francisco | E3: CA | F3: 94121 | G3: 301-830-0735 | H3: ben.spielman1223@gmail.com | I3: BRA | J3: 2025/09/20 | K3: 2 | L3: 1 | M3: =K3*L3 -> 2 | Q3: 251021t205900 | R3: 3 | S3: PGH | T3: 26 | U3: 1 | V3: 17 | W3: 26 | X3: 1 | Y3: 19 | Z3: =1000*(W3-T3)+100*(X3-U3)+(Y3-V3) -> 2 | AA3: 6 | AB3: D | AC3: Y | AE3: =(CODE(MID(H3,1,1))-43)+(CODE(MID(H3,2,1))-43)*80+(CODE(MID(H3,3,1))-43)*80*80+(CODE(MID(H3,4,1))-43)*80*80*80 -> 1969495 | AF3: =OR($S3="BEN",NOT(ISERROR(SEARCH("H",$AB3)))) -> FALSE | AG3: =OR($S3="BRA",NOT(ISERROR(SEARCH("H",$AB3)))) -> FALSE | AH3: =OR($S3="PGH",NOT(ISERROR(SEARCH("H",$AB3)))) -> TRUE | AI3: =OR($S3="LUD",NOT(ISERROR(SEARCH("H",$AB3)))) -> FALSE | AJ3: =DATE(T3+2000,U3,V3) -> 44577 | AK3: =DATE(2000+W3,X3,Y3) -> 44579 | AL3: =VALUE(RIGHT(R3,1)) -> 3 | AM3: =AA3 -> 6 | AN3: =IF(ISERROR(SEARCH("N",$AB3)),AM3,MAX(AM3-4,4)) -> 6
A4: Leo | B4: Stanislaus | C4: 1874 Mohican Dr. | D4: South Lake Tahoe | E4: CA | G4: 818-930-2028 | H4: leo.stanislas@gmail.com | I4: BEN | J4: 2025/07/12 | K4: 2 | L4: 1 | M4: 2 | Q4: 251031t110700 | R4: 1 | S4: BEN | T4: 26 | U4: 3 | V4: 13 | W4: 26 | X4: 3 | Y4: 14 | Z4: =1000*(W4-T4)+100*(X4-U4)+(Y4-V4) -> 1 | AA4: 12 | AC4: Y | AE4: =(CODE(MID(H4,1,1))-43)+(CODE(MID(H4,2,1))-43)*80+(CODE(MID(H4,3,1))-43)*80*80+(CODE(MID(H4,4,1))-43)*80*80*80 -> 1975905 | AF4: =OR($S4="BEN",NOT(ISERROR(SEARCH("H",$AB4)))) -> TRUE | AG4: =OR($S4="BRA",NOT(ISERROR(SEARCH("H",$AB4)))) -> FALSE | AH4: =OR($S4="PGH",NOT(ISERROR(SEARCH("H",$AB4)))) -> FALSE | AI4: =OR($S4="LUD",NOT(ISERROR(SEARCH("H",$AB4)))) -> FALSE | AJ4: =DATE(T4+2000,U4,V4) -> 44632 | AK4: =DATE(2000+W4,X4,Y4) -> 44633 | AL4: =VALUE(RIGHT(R4,1)) -> 1 | AM4: =AA4 -> 12 | AN4: =IF(ISERROR(SEARCH("N",$AB4)),AM4,MAX(AM4-4,4)) -> 12
A5: Leo | B5: Stanislaus | C5: 1874 Mohican Dr. | D5: South Lake Tahoe | E5: CA | G5: 818-930-2028 | H5: leo.stanislas@gmail.com | I5: BEN | J5: 2025/07/12 | K5: 2 | L5: 1 | M5: 2 | Q5: 251031t110700 | R5: 1 | S5: BRA | T5: 26 | U5: 3 | V5: 14 | W5: 26 | X5: 3 | Y5: 15 | Z5: =1000*(W5-T5)+100*(X5-U5)+(Y5-V5) -> 1 | AA5: 15 | AC5: Y | AE5: =(CODE(MID(H5,1,1))-43)+(CODE(MID(H5,2,1))-43)*80+(CODE(MID(H5,3,1))-43)*80*80+(CODE(MID(H5,4,1))-43)*80*80*80 -> 1975905 | AF5: =OR($S5="BEN",NOT(ISERROR(SEARCH("H",$AB5)))) -> FALSE | AG5: =OR($S5="BRA",NOT(ISERROR(SEARCH("H",$AB5)))) -> TRUE | AH5: =OR($S5="PGH",NOT(ISERROR(SEARCH("H",$AB5)))) -> FALSE | AI5: =OR($S5="LUD",NOT(ISERROR(SEARCH("H",$AB5)))) -> FALSE | AJ5: =DATE(T5+2000,U5,V5) -> 44633 | AK5: =DATE(2000+W5,X5,Y5) -> 44634 | AL5: =VALUE(RIGHT(R5,1)) -> 1 | AM5: =AA5 -> 15 | AN5: =IF(ISERROR(SEARCH("N",$AB5)),AM5,MAX(AM5-4,4)) -> 15
A6: Dick | B6: Simpson | C6: 3326 Kipling St. | D6: Palo Alto | E6: CA | F6: 94306 | G6: 650-494-9272 | H6: hut.coord@yahoo.com | I6: PGH | J6: 2025/07/19 | K6: 13 | L6: 1 | M6: 14 | N6: Leader | O6: L | P6: LPC STS | Q6: 251022t085900 | R6: 1 | S6: PGH | T6: 26 | U6: 1 | V6: 30 | W6: 26 | X6: 2 | Y6: 1 | Z6: 2 | AA6: 15 | AC6: Y | AE6: =(CODE(MID(H6,1,1))-43)+(CODE(MID(H6,2,1))-43)*80+(CODE(MID(H6,3,1))-43)*80*80+(CODE(MID(H6,4,1))-43)*80*80*80 -> 2009181 | AF6: =OR($S6="BEN",NOT(ISERROR(SEARCH("H",$AB6)))) -> FALSE | AG6: =OR($S6="BRA",NOT(ISERROR(SEARCH("H",$AB6)))) -> FALSE | AH6: =OR($S6="PGH",NOT(ISERROR(SEARCH("H",$AB6)))) -> TRUE | AI6: =OR($S6="LUD",NOT(ISERROR(SEARCH("H",$AB6)))) -> FALSE | AJ6: =DATE(T6+2000,U6,V6) -> 44590 | AK6: =DATE(2000+W6,X6,Y6) -> 44592 | AL6: =VALUE(RIGHT(R6,1)) -> 1 | AM6: =AA6 -> 15 | AN6: =IF(ISERROR(SEARCH("N",$AB6)),AM6,MAX(AM6-4,4)) -> 15
A7: Teddy | B7: Koerner | C7: 1275 McAllister | D7: San Francisco | E7: CA | G7: 303-956-0501 | H7: tk6174@gmail.com | I7: LUD | J7: 2025/10/04 | K7: 2 | L7: 1 | M7: =K7*L7 -> 2 | Q7: 251029t151000 | R7: 4 | S7: LUD | T7: 26 | U7: 3 | V7: 6 | W7: 26 | X7: 3 | Y7: 8 | Z7: =1000*(W7-T7)+100*(X7-U7)+(Y7-V7) -> 2 | AA7: 15 | AC7: Y | AE7: =(CODE(MID(H7,1,1))-43)+(CODE(MID(H7,2,1))-43)*80+(CODE(MID(H7,3,1))-43)*80*80+(CODE(MID(H7,4,1))-43)*80*80*80 -> 3147593 | AF7: =OR($S7="BEN",NOT(ISERROR(SEARCH("H",$AB7)))) -> FALSE | AG7: =OR($S7="BRA",NOT(ISERROR(SEARCH("H",$AB7)))) -> FALSE | AH7: =OR($S7="PGH",NOT(ISERROR(SEARCH("H",$AB7)))) -> FALSE | AI7: =OR($S7="LUD",NOT(ISERROR(SEARCH("H",$AB7)))) -> TRUE | AJ7: =DATE(T7+2000,U7,V7) -> 44625 | AK7: =DATE(2000+W7,X7,Y7) -> 44627 | AL7: =VALUE(RIGHT(R7,1)) -> 4 | AM7: =AA7 -> 15 | AN7: =IF(ISERROR(SEARCH("N",$AB7)),AM7,MAX(AM7-4,4)) -> 15
A8: Ethan | B8: Kennon | C8: 1270 Storey Ave D | D8: San Francisco | E8: CA | F8: 94129 | G8: 707-315-9872 | H8: elk1234567@yahoo.com | I8: PGH | J8: 2025/08/16 | K8: 4 | L8: 1 | M8: =K8*L8 -> 4 | N8: Leader | O8: L | Q8: 251028t110400 | R8: 1 | S8: BEN | T8: 26 | U8: 1 | V8: 16 | W8: 26 | X8: 1 | Y8: 19 | Z8: =1000*(W8-T8)+100*(X8-U8)+(Y8-V8) -> 3 | AA8: 12 | AB8: N | AC8: Y | AE8: =(CODE(MID(H8,1,1))-43)+(CODE(MID(H8,2,1))-43)*80+(CODE(MID(H8,3,1))-43)*80*80+(CODE(MID(H8,4,1))-43)*80*80*80 -> 3486858 | AF8: =OR($S8="BEN",NOT(ISERROR(SEARCH("H",$AB8)))) -> TRUE | AG8: =OR($S8="BRA",NOT(ISERROR(SEARCH("H",$AB8)))) -> FALSE | AH8: =OR($S8="PGH",NOT(ISERROR(SEARCH("H",$AB8)))) -> FALSE | AI8: =OR($S8="LUD",NOT(ISERROR(SEARCH("H",$AB8)))) -> FALSE | AJ8: =DATE(T8+2000,U8,V8) -> 44576 | AK8: =DATE(2000+W8,X8,Y8) -> 44579 | AL8: =VALUE(RIGHT(R8,1)) -> 1 | AM8: =AA8 -> 12 | AN8: =IF(ISERROR(SEARCH("N",$AB8)),AM8,MAX(AM8-4,4)) -> 8
A9: Scott | B9: Bennett | C9: 1476 Valencia - Apt 12 | D9: San Francisco | E9: CA | F9: 94110 | G9: 650-283-9916 | H9: st1993@gmail.com | I9: PGH | J9: 2025/08/16 | K9: 2 | L9: 1 | M9: =K9*L9 -> 2 | Q9: 251025t195500 | R9: 1 | S9: PGH | T9: 26 | U9: 1 | V9: 17 | W9: 26 | X9: 1 | Y9: 19 | Z9: =1000*(W9-T9)+100*(X9-U9)+(Y9-V9) -> 2 | AA9: 6 | AC9: Y | AE9: =(CODE(MID(H9,1,1))-43)+(CODE(MID(H9,2,1))-43)*80+(CODE(MID(H9,3,1))-43)*80*80+(CODE(MID(H9,4,1))-43)*80*80*80 -> 7212312 | AF9: =OR($S9="BEN",NOT(ISERROR(SEARCH("H",$AB9)))) -> FALSE | AG9: =OR($S9="BRA",NOT(ISERROR(SEARCH("H",$AB9)))) -> FALSE | AH9: =OR($S9="PGH",NOT(ISERROR(SEARCH("H",$AB9)))) -> TRUE | AI9: =OR($S9="LUD",NOT(ISERROR(SEARCH("H",$AB9)))) -> FALSE | AJ9: =DATE(T9+2000,U9,V9) -> 44577 | AK9: =DATE(2000+W9,X9,Y9) -> 44579 | AL9: =VALUE(RIGHT(R9,1)) -> 1 | AM9: =AA9 -> 6 | AN9: =IF(ISERROR(SEARCH("N",$AB9)),AM9,MAX(AM9-4,4)) -> 6
A10: Hal | B10: Tompkins | C10: 3134 Oak Knoll Drive | D10: Redwood City | E10: CA | F10: 94062 | G10: 650-400-8351 | H10: hal_tompkins@yahoo.com | I10: BRA | J10: 2025/09/20 | K10: 2 | L10: 1 | M10: =K10*L10 -> 2 | N10: Leader | O10: L | P10: LPC STS | Q10: 251025t073200 | R10: 1 | S10: BRA | T10: 26 | U10: 1 | V10: 24 | W10: 26 | X10: 1 | Y10: 26 | Z10: =1000*(W10-T10)+100*(X10-U10)+(Y10-V10) -> 2 | AA10: 15 | AC10: Y | AE10: =(CODE(MID(H10,1,1))-43)+(CODE(MID(H10,2,1))-43)*80+(CODE(MID(H10,3,1))-43)*80*80+(CODE(MID(H10,4,1))-43)*80*80*80 -> 27044381 | AF10: =OR($S10="BEN",NOT(ISERROR(SEARCH("H",$AB10)))) -> FALSE | AG10: =OR($S10="BRA",NOT(ISERROR(SEARCH("H",$AB10)))) -> TRUE | AH10: =OR($S10="PGH",NOT(ISERROR(SEARCH("H",$AB10)))) -> FALSE | AI10: =OR($S10="LUD",NOT(ISERROR(SEARCH("H",$AB10)))) -> FALSE | AJ10: =DATE(T10+2000,U10,V10) -> 44584 | AK10: =DATE(2000+W10,X10,Y10) -> 44586 | AL10: =VALUE(RIGHT(R10,1)) -> 1 | AM10: =AA10 -> 15 | AN10: =IF(ISERROR(SEARCH("N",$AB10)),AM10,MAX(AM10-4,4)) -> 15
A11: Sarah | B11: MacPherson | C11: 1350 Pine St. | D11: San Francisco | E11: CA | F11: 94109 | G11: 650-334-1015 | H11: sjmac650@gmail.com | I11: BRA | J11: 2025/09/20 | K11: 2 | L11: 1 | M11: =K11*L11 -> 2 | Q11: 251031t124000 | R11: 1 | S11: BRA | T11: 26 | U11: 1 | V11: 15 | W11: 26 | X11: 1 | Y11: 18 | Z11: =1000*(W11-T11)+100*(X11-U11)+(Y11-V11) -> 3 | AA11: 6 | AB11: DN | AC11: Y | AE11: =(CODE(MID(H11,1,1))-43)+(CODE(MID(H11,2,1))-43)*80+(CODE(MID(H11,3,1))-43)*80*80+(CODE(MID(H11,4,1))-43)*80*80*80 -> 28075512 | AF11: =OR($S11="BEN",NOT(ISERROR(SEARCH("H",$AB11)))) -> FALSE | AG11: =OR($S11="BRA",NOT(ISERROR(SEARCH("H",$AB11)))) -> TRUE | AH11: =OR($S11="PGH",NOT(ISERROR(SEARCH("H",$AB11)))) -> FALSE | AI11: =OR($S11="LUD",NOT(ISERROR(SEARCH("H",$AB11)))) -> FALSE | AJ11: =DATE(T11+2000,U11,V11) -> 44575 | AK11: =DATE(2000+W11,X11,Y11) -> 44578 | AL11: =VALUE(RIGHT(R11,1)) -> 1 | AM11: =AA11 -> 6 | AN11: =IF(ISERROR(SEARCH("N",$AB11)),AM11,MAX(AM11-4,4)) -> 4
A12: Anna | B12: O'Malley | D12: San Francisco | E12: CA | G12: 802-540-5101 | H12: aomalley17@gmail.com | I12: PGH | J12: 2025/07/19 | K12: 2 | L12: 1 | M12: =K12*L12 -> 2 | Q12: 251029t154700 | R12: 2 | S12: BEN | T12: 26 | U12: 3 | V12: 14 | W12: 26 | X12: 3 | Y12: 15 | Z12: =1000*(W12-T12)+100*(X12-U12)+(Y12-V12) -> 1 | AA12: 7 | AB12: N | AC12: Y | AE12: =(CODE(MID(H12,1,1))-43)+(CODE(MID(H12,2,1))-43)*80+(CODE(MID(H12,3,1))-43)*80*80+(CODE(MID(H12,4,1))-43)*80*80*80 -> 28075894 | AF12: =OR($S12="BEN",NOT(ISERROR(SEARCH("H",$AB12)))) -> TRUE | AG12: =OR($S12="BRA",NOT(ISERROR(SEARCH("H",$AB12)))) -> FALSE | AH12: =OR($S12="PGH",NOT(ISERROR(SEARCH("H",$AB12)))) -> FALSE | AI12: =OR($S12="LUD",NOT(ISERROR(SEARCH("H",$AB12)))) -> FALSE | AJ12: =DATE(T12+2000,U12,V12) -> 44633 | AK12: =DATE(2000+W12,X12,Y12) -> 44634 | AL12: =VALUE(RIGHT(R12,1)) -> 2 | AM12: =AA12 -> 7 | AN12: =IF(ISERROR(SEARCH("N",$AB12)),AM12,MAX(AM12-4,4)) -> 4
A13: David | B13: Passmore | C13: 2368 21st Ave | D13: San Francisco | E13: CA | F13: 94116 | G13: 650-215-0374 | H13: d1passmore@yahoo.com | I13: BRA | J13: 2025/09/20 | K13: 2 | L13: 1 | M13: =K13*L13 -> 2 | Q13: 251103t180200 | R13: S1 | S13: BRA | T13: 26 | U13: 3 | V13: 15 | W13: 26 | X13: 3 | Y13: 17 | Z13: =1000*(W13-T13)+100*(X13-U13)+(Y13-V13) -> 2 | AA13: 10 | AB13: N | AC13: Y | AD13: completed | AE13: =(CODE(MID(H13,1,1))-43)+(CODE(MID(H13,2,1))-43)*80+(CODE(MID(H13,3,1))-43)*80*80+(CODE(MID(H13,4,1))-43)*80*80*80 -> 28090137 | AF13: =OR($S13="BEN",NOT(ISERROR(SEARCH("H",$AB13)))) -> FALSE | AG13: =OR($S13="BRA",NOT(ISERROR(SEARCH("H",$AB13)))) -> TRUE | AH13: =OR($S13="PGH",NOT(ISERROR(SEARCH("H",$AB13)))) -> FALSE | AI13: =OR($S13="LUD",NOT(ISERROR(SEARCH("H",$AB13)))) -> FALSE | AJ13: =DATE(T13+2000,U13,V13) -> 44634 | AK13: =DATE(2000+W13,X13,Y13) -> 44636 | AL13: =VALUE(RIGHT(R13,1)) -> 1 | AM13: =AA13 -> 10 | AN13: =IF(ISERROR(SEARCH("N",$AB13)),AM13,MAX(AM13-4,4)) -> 6
A14: Kate | B14: Radu | C14: 15 Skylonda Drive | D14: Redwood City | E14: CA | F14: 94062 | G14: 214-402-3918 | H14: karadu422@gmail.com | I14: PGH | J14: 2025/08/23 | K14: 2 | L14: 1 | M14: =K14*L14 -> 2 | Q14: 251028t114100 | R14: 1 | S14: PGH | T14: 26 | U14: 2 | V14: 27 | W14: 26 | X14: 3 | Y14: 2 | Z14: 3 | AA14: 15 | AC14: Y | AE14: =(CODE(MID(H14,1,1))-43)+(CODE(MID(H14,2,1))-43)*80+(CODE(MID(H14,3,1))-43)*80*80+(CODE(MID(H14,4,1))-43)*80*80*80 -> 28106784 | AF14: =OR($S14="BEN",NOT(ISERROR(SEARCH("H",$AB14)))) -> FALSE | AG14: =OR($S14="BRA",NOT(ISERROR(SEARCH("H",$AB14)))) -> FALSE | AH14: =OR($S14="PGH",NOT(ISERROR(SEARCH("H",$AB14)))) -> TRUE | AI14: =OR($S14="LUD",NOT(ISERROR(SEARCH("H",$AB14)))) -> FALSE | AJ14: =DATE(T14+2000,U14,V14) -> 44618 | AK14: =DATE(2000+W14,X14,Y14) -> 44621 | AL14: =VALUE(RIGHT(R14,1)) -> 1 | AM14: =AA14 -> 15 | AN14: =IF(ISERROR(SEARCH("N",$AB14)),AM14,MAX(AM14-4,4)) -> 15
A15: Rani | B15: Zimand | C15: 10145 Morris Valley Rd | D15: Truckee | E15: CA | G15: 301-502-1345 | H15: liranzimand@gmail.com | I15: BEN | J15: 2025/09/30 | K15: 1 | L15: 1 | M15: =K15*L15 -> 1 | Q15: 251106t064100 | R15: S1 | S15: PGH | T15: 26 | U15: 2 | V15: 13 | W15: 26 | X15: 2 | Y15: 14 | Z15: =1000*(W15-T15)+100*(X15-U15)+(Y15-V15) -> 1 | AA15: 15 | AC15: Y | AE15: =(CODE(MID(H15,1,1))-43)+(CODE(MID(H15,2,1))-43)*80+(CODE(MID(H15,3,1))-43)*80*80+(CODE(MID(H15,4,1))-43)*80*80*80 -> 28107425 | AF15: =OR($S15="BEN",NOT(ISERROR(SEARCH("H",$AB15)))) -> FALSE | AG15: =OR($S15="BRA",NOT(ISERROR(SEARCH("H",$AB15)))) -> FALSE | AH15: =OR($S15="PGH",NOT(ISERROR(SEARCH("H",$AB15)))) -> TRUE | AI15: =OR($S15="LUD",NOT(ISERROR(SEARCH("H",$AB15)))) -> FALSE | AJ15: =DATE(T15+2000,U15,V15) -> 44604 | AK15: =DATE(2000+W15,X15,Y15) -> 44605 | AL15: =VALUE(RIGHT(R15,1)) -> 1 | AM15: =AA15 -> 15 | AN15: =IF(ISERROR(SEARCH("N",$AB15)),AM15,MAX(AM15-4,4)) -> 15
A16: Benjamin | B16: Raudabaugh | C16: 15 Stoneman St. | D16: San Francisco | E16: CA | F16: 94110 | G16: 415-713-1422 | H16: bjraudabaugh@gmail.com | I16: LUD | J16: 2025/10/04 | K16: 2 | L16: 1 | M16: =K16*L16 -> 2 | Q16: 251101t094545 | R16: 9 | S16: PGH | T16: 26 | U16: 4 | V16: 25 | W16: 26 | X16: 4 | Y16: 27 | Z16: =1000*(W16-T16)+100*(X16-U16)+(Y16-V16) -> 2 | AA16: 15 | AC16: Y | AE16: =(CODE(MID(H16,1,1))-43)+(CODE(MID(H16,2,1))-43)*80+(CODE(MID(H16,3,1))-43)*80*80+(CODE(MID(H16,4,1))-43)*80*80*80 -> 28107495 | AF16: =OR($S16="BEN",NOT(ISERROR(SEARCH("H",$AB16)))) -> FALSE | AG16: =OR($S16="BRA",NOT(ISERROR(SEARCH("H",$AB16)))) -> FALSE | AH16: =OR($S16="PGH",NOT(ISERROR(SEARCH("H",$AB16)))) -> TRUE | AI16: =OR($S16="LUD",NOT(ISERROR(SEARCH("H",$AB16)))) -> FALSE | AJ16: =DATE(T16+2000,U16,V16) -> 44675 | AK16: =DATE(2000+W16,X16,Y16) -> 44677 | AL16: =VALUE(RIGHT(R16,1)) -> 9 | AM16: =AA16 -> 15 | AN16: =IF(ISERROR(SEARCH("N",$AB16)),AM16,MAX(AM16-4,4)) -> 15
A17: Michelle | B17: Trame | C17: 522 66th St. | D17: Oakland | E17: CA | F17: 94609 | G17: 310-920-6071 | H17: notactuallymichelle@gmail.com | I17: BEN | J17: 2025/07/12 | K17: 2 | L17: 1 | M17: 2 | Q17: 251030t190700 | R17: 3 | S17: BRA | T17: 26 | U17: 3 | V17: 20 | W17: 26 | X17: 3 | Y17: 22 | Z17: =1000*(W17-T17)+100*(X17-U17)+(Y17-V17) -> 2 | AA17: 7 | AB17: N | AC17: Y | AE17: =(CODE(MID(H17,1,1))-43)+(CODE(MID(H17,2,1))-43)*80+(CODE(MID(H17,3,1))-43)*80*80+(CODE(MID(H17,4,1))-43)*80*80*80 -> 28120707 | AF17: =OR($S17="BEN",NOT(ISERROR(SEARCH("H",$AB17)))) -> FALSE | AG17: =OR($S17="BRA",NOT(ISERROR(SEARCH("H",$AB17)))) -> TRUE | AH17: =OR($S17="PGH",NOT(ISERROR(SEARCH("H",$AB17)))) -> FALSE | AI17: =OR($S17="LUD",NOT(ISERROR(SEARCH("H",$AB17)))) -> FALSE | AJ17: =DATE(T17+2000,U17,V17) -> 44639 | AK17: =DATE(2000+W17,X17,Y17) -> 44641 | AL17: =VALUE(RIGHT(R17,1)) -> 3 | AM17: =AA17 -> 7 | AN17: =IF(ISERROR(SEARCH("N",$AB17)),AM17,MAX(AM17-4,4)) -> 4
A18: Amy | B18: Burdick | C18: 10145 Morris Valley Rd | D18: Truckee | E18: CA | G18: 578-859-4519 | H18: amyburdick20@gmail.com | I18: BEN | J18: 2025/09/30 | K18: 1 | L18: 1 | M18: =K18*L18 -> 1 | Q18: 251027t211700 | R18: 1 | S18: BRA | T18: 26 | U18: 3 | V18: 10 | W18: 26 | X18: 3 | Y18: 12 | Z18: =1000*(W18-T18)+100*(X18-U18)+(Y18-V18) -> 2 | AA18: 15 | AC18: Y | AE18: =(CODE(MID(H18,1,1))-43)+(CODE(MID(H18,2,1))-43)*80+(CODE(MID(H18,3,1))-43)*80*80+(CODE(MID(H18,4,1))-43)*80*80*80 -> 28664534 | AF18: =OR($S18="BEN",NOT(ISERROR(SEARCH("H",$AB18)))) -> FALSE | AG18: =OR($S18="BRA",NOT(ISERROR(SEARCH("H",$AB18)))) -> TRUE | AH18: =OR($S18="PGH",NOT(ISERROR(SEARCH("H",$AB18)))) -> FALSE | AI18: =OR($S18="LUD",NOT(ISERROR(SEARCH("H",$AB18)))) -> FALSE | AJ18: =DATE(T18+2000,U18,V18) -> 44629 | AK18: =DATE(2000+W18,X18,Y18) -> 44631 | AL18: =VALUE(RIGHT(R18,1)) -> 1 | AM18: =AA18 -> 15 | AN18: =IF(ISERROR(SEARCH("N",$AB18)),AM18,MAX(AM18-4,4)) -> 15
A19: Tracy | B19: Ballinger | G19: 385-487-3057 | H19: tracyballinger@gmail.com | I19: BEN | J19: 2025/09/19 | K19: 2 | L19: 1 | M19: =K19*L19 -> 2 | Q19: 251031t100500 | R19: 1 | S19: LUD | T19: 26 | U19: 2 | V19: 14 | W19: 26 | X19: 2 | Y19: 16 | Z19: =1000*(W19-T19)+100*(X19-U19)+(Y19-V19) -> 2 | AA19: 8 | AB19: HDN | AC19: Y | AE19: =(CODE(MID(H19,1,1))-43)+(CODE(MID(H19,2,1))-43)*80+(CODE(MID(H19,3,1))-43)*80*80+(CODE(MID(H19,4,1))-43)*80*80*80 -> 29023353 | AF19: =OR($S19="BEN",NOT(ISERROR(SEARCH("H",$AB19)))) -> TRUE | AG19: =OR($S19="BRA",NOT(ISERROR(SEARCH("H",$AB19)))) -> TRUE | AH19: =OR($S19="PGH",NOT(ISERROR(SEARCH("H",$AB19)))) -> TRUE | AI19: =OR($S19="LUD",NOT(ISERROR(SEARCH("H",$AB19)))) -> TRUE | AJ19: =DATE(T19+2000,U19,V19) -> 44605 | AK19: =DATE(2000+W19,X19,Y19) -> 44607 | AL19: =VALUE(RIGHT(R19,1)) -> 1 | AM19: =AA19 -> 8 | AN19: =IF(ISERROR(SEARCH("N",$AB19)),AM19,MAX(AM19-4,4)) -> 4
A20: Tracy | B20: Cuneo | D20: Truckee | E20: CA | G20: 530-414-6197 | H20: tracy@compnetworks.com | I20: PGH | J20: 2025/07/19 | K20: 2 | L20: 1 | M20: =K20*L20 -> 2 | Q20: 251021t153000 | R20: 5 | S20: BRA | T20: 26 | U20: 4 | V20: 10 | W20: 26 | X20: 4 | Y20: 12 | Z20: =1000*(W20-T20)+100*(X20-U20)+(Y20-V20) -> 2 | AA20: 9 | AC20: Y | AE20: =(CODE(MID(H20,1,1))-43)+(CODE(MID(H20,2,1))-43)*80+(CODE(MID(H20,3,1))-43)*80*80+(CODE(MID(H20,4,1))-43)*80*80*80 -> 29023353 | AF20: =OR($S20="BEN",NOT(ISERROR(SEARCH("H",$AB20)))) -> FALSE | AG20: =OR($S20="BRA",NOT(ISERROR(SEARCH("H",$AB20)))) -> TRUE | AH20: =OR($S20="PGH",NOT(ISERROR(SEARCH("H",$AB20)))) -> FALSE | AI20: =OR($S20="LUD",NOT(ISERROR(SEARCH("H",$AB20)))) -> FALSE | AJ20: =DATE(T20+2000,U20,V20) -> 44660 | AK20: =DATE(2000+W20,X20,Y20) -> 44662 | AL20: =VALUE(RIGHT(R20,1)) -> 5 | AM20: =AA20 -> 9 | AN20: =IF(ISERROR(SEARCH("N",$AB20)),AM20,MAX(AM20-4,4)) -> 9
A21: Jared | B21: Deck | C21: 9217 Los Puentes | D21: Newcastle | E21: CA | G21: 508-207-5771 | H21: jdeck8@gmail.com | I21: PGH | J21: 2025/10/04 | K21: 2 | L21: 1 | M21: =K21*L21 -> 2 | Q21: 251029t125700 | R21: 1 | S21: PGH | T21: 25 | U21: 12 | V21: 30 | W21: 26 | X21: 1 | Y21: 1 | Z21: 2 | AA21: 15 | AC21: Y | AE21: =(CODE(MID(H21,1,1))-43)+(CODE(MID(H21,2,1))-43)*80+(CODE(MID(H21,3,1))-43)*80*80+(CODE(MID(H21,4,1))-43)*80*80*80 -> 29047823 | AF21: =OR($S21="BEN",NOT(ISERROR(SEARCH("H",$AB21)))) -> FALSE | AG21: =OR($S21="BRA",NOT(ISERROR(SEARCH("H",$AB21)))) -> FALSE | AH21: =OR($S21="PGH",NOT(ISERROR(SEARCH("H",$AB21)))) -> TRUE | AI21: =OR($S21="LUD",NOT(ISERROR(SEARCH("H",$AB21)))) -> FALSE | AJ21: =DATE(T21+2000,U21,V21) -> 44559 | AK21: =DATE(2000+W21,X21,Y21) -> 44561 | AL21: =VALUE(RIGHT(R21,1)) -> 1 | AM21: =AA21 -> 15 | AN21: =IF(ISERROR(SEARCH("N",$AB21)),AM21,MAX(AM21-4,4)) -> 15
A22: Katie | B22: McRae | C22: 1200 Cabrolet Drive | D22: Carson City | E22: NV | F22: 89703 | G22: 775-220-9792 | H22: kamcrae@yahoo.com | I22: MUL | J22: 2025/08/20 | K22: 3 | L22: 1 | M22: =K22*L22 -> 3 | Q22: 251029t123100 | R22: 2 | S22: BRA | T22: 26 | U22: 1 | V22: 18 | W22: 26 | X22: 1 | Y22: 20 | Z22: =1000*(W22-T22)+100*(X22-U22)+(Y22-V22) -> 2 | AA22: 4 | AC22: Y | AE22: =(CODE(MID(H22,1,1))-43)+(CODE(MID(H22,2,1))-43)*80+(CODE(MID(H22,3,1))-43)*80*80+(CODE(MID(H22,4,1))-43)*80*80*80 -> 29098784 | AF22: =OR($S22="BEN",NOT(ISERROR(SEARCH("H",$AB22)))) -> FALSE | AG22: =OR($S22="BRA",NOT(ISERROR(SEARCH("H",$AB22)))) -> TRUE | AH22: =OR($S22="PGH",NOT(ISERROR(SEARCH("H",$AB22)))) -> FALSE | AI22: =OR($S22="LUD",NOT(ISERROR(SEARCH("H",$AB22)))) -> FALSE | AJ22: =DATE(T22+2000,U22,V22) -> 44578 | AK22: =DATE(2000+W22,X22,Y22) -> 44580 | AL22: =VALUE(RIGHT(R22,1)) -> 2 | AM22: =AA22 -> 4 | AN22: =IF(ISERROR(SEARCH("N",$AB22)),AM22,MAX(AM22-4,4)) -> 4
A23: Brian | B23: McRae | G23: 775-230-4338 | H23: bemcrae@yahoo.com | I23: BEN | J23: 2025/09/19 | K23: 2 | L23: 1 | M23: =K23*L23 -> 2 | Q23: 251030t145900 | R23: 1 | S23: BEN | T23: 26 | U23: 2 | V23: 8 | W23: 26 | X23: 2 | Y23: 10 | Z23: =1000*(W23-T23)+100*(X23-U23)+(Y23-V23) -> 2 | AA23: 4 | AC23: Y | AE23: =(CODE(MID(H23,1,1))-43)+(CODE(MID(H23,2,1))-43)*80+(CODE(MID(H23,3,1))-43)*80*80+(CODE(MID(H23,4,1))-43)*80*80*80 -> 29099095 | AF23: =OR($S23="BEN",NOT(ISERROR(SEARCH("H",$AB23)))) -> TRUE | AG23: =OR($S23="BRA",NOT(ISERROR(SEARCH("H",$AB23)))) -> FALSE | AH23: =OR($S23="PGH",NOT(ISERROR(SEARCH("H",$AB23)))) -> FALSE | AI23: =OR($S23="LUD",NOT(ISERROR(SEARCH("H",$AB23)))) -> FALSE | AJ23: =DATE(T23+2000,U23,V23) -> 44599 | AK23: =DATE(2000+W23,X23,Y23) -> 44601 | AL23: =VALUE(RIGHT(R23,1)) -> 1 | AM23: =AA23 -> 4 | AN23: =IF(ISERROR(SEARCH("N",$AB23)),AM23,MAX(AM23-4,4)) -> 4
A24: Hannah | B24: Mitchell | C24: 449 Valle Vista Ave | D24: Oakland | E24: CA | F24: 94610 | G24: 510-282-2108 | H24: mitchell.hannah@gmail.com | I24: CON | J24: 2025/10/18 | K24: 1 | L24: 1 | M24: =K24*L24 -> 1 | Q24: 251029t123700 | R24: 1 | S24: BRA | T24: 26 | U24: 2 | V24: 28 | W24: 26 | X24: 3 | Y24: 1 | Z24: 1 | AA24: 4 | AD24: declined | AE24: =(CODE(MID(H24,1,1))-43)+(CODE(MID(H24,2,1))-43)*80+(CODE(MID(H24,3,1))-43)*80*80+(CODE(MID(H24,4,1))-43)*80*80*80 -> 29144226 | AF24: =OR($S24="BEN",NOT(ISERROR(SEARCH("H",$AB24)))) -> FALSE | AG24: =OR($S24="BRA",NOT(ISERROR(SEARCH("H",$AB24)))) -> TRUE | AH24: =OR($S24="PGH",NOT(ISERROR(SEARCH("H",$AB24)))) -> FALSE | AI24: =OR($S24="LUD",NOT(ISERROR(SEARCH("H",$AB24)))) -> FALSE | AJ24: =DATE(T24+2000,U24,V24) -> 44619 | AK24: =DATE(2000+W24,X24,Y24) -> 44620 | AL24: =VALUE(RIGHT(R24,1)) -> 1 | AM24: =AA24 -> 4 | AN24: =IF(ISERROR(SEARCH("N",$AB24)),AM24,MAX(AM24-4,4)) -> 4
A25: Amy | B25: Chen | C25: 175 Bluxome #223 | D25: San Francisco | E25: CA | F25: 94107 | G25: 248-321-0848 | H25: amychen2012@gmail.com | I25: PGH | J25: 2025/10/04 | K25: 2 | L25: 1 | M25: =K25*L25 -> 2 | Q25: 251030t202000 | R25: 4 | S25: BEN | T25: 26 | U25: 3 | V25: 21 | W25: 26 | X25: 3 | Y25: 22 | Z25: =1000*(W25-T25)+100*(X25-U25)+(Y25-V25) -> 1 | AA25: 7 | AB25: N | AC25: YF | AE25: =(CODE(MID(H25,1,1))-43)+(CODE(MID(H25,2,1))-43)*80+(CODE(MID(H25,3,1))-43)*80*80+(CODE(MID(H25,4,1))-43)*80*80*80 -> 29176534 | AF25: =OR($S25="BEN",NOT(ISERROR(SEARCH("H",$AB25)))) -> TRUE | AG25: =OR($S25="BRA",NOT(ISERROR(SEARCH("H",$AB25)))) -> FALSE | AH25: =OR($S25="PGH",NOT(ISERROR(SEARCH("H",$AB25)))) -> FALSE | AI25: =OR($S25="LUD",NOT(ISERROR(SEARCH("H",$AB25)))) -> FALSE | AJ25: =DATE(T25+2000,U25,V25) -> 44640 | AK25: =DATE(2000+W25,X25,Y25) -> 44641 | AL25: =VALUE(RIGHT(R25,1)) -> 4 | AM25: =AA25 -> 7 | AN25: =IF(ISERROR(SEARCH("N",$AB25)),AM25,MAX(AM25-4,4)) -> 4
A26: Jon | B26: Little | C26: 4057a 24th St | D26: San Francisco | E26: CA | F26: 94117 | G26: 802-318-8831 | H26: jondlittle@gmail.com | I26: PGH | J26: 2025/10/04 | K26: 2 | L26: 1 | M26: =K26*L26 -> 2 | Q26: 251030t193600 | R26: 2 | S26: BEN | T26: 26 | U26: 1 | V26: 23 | W26: 26 | X26: 1 | Y26: 25 | Z26: =1000*(W26-T26)+100*(X26-U26)+(Y26-V26) -> 2 | AA26: 8 | AC26: Y | AE26: =(CODE(MID(H26,1,1))-43)+(CODE(MID(H26,2,1))-43)*80+(CODE(MID(H26,3,1))-43)*80*80+(CODE(MID(H26,4,1))-43)*80*80*80 -> 29618303 | AF26: =OR($S26="BEN",NOT(ISERROR(SEARCH("H",$AB26)))) -> TRUE | AG26: =OR($S26="BRA",NOT(ISERROR(SEARCH("H",$AB26)))) -> FALSE | AH26: =OR($S26="PGH",NOT(ISERROR(SEARCH("H",$AB26)))) -> FALSE | AI26: =OR($S26="LUD",NOT(ISERROR(SEARCH("H",$AB26)))) -> FALSE | AJ26: =DATE(T26+2000,U26,V26) -> 44583 | AK26: =DATE(2000+W26,X26,Y26) -> 44585 | AL26: =VALUE(RIGHT(R26,1)) -> 2 | AM26: =AA26 -> 8 | AN26: =IF(ISERROR(SEARCH("N",$AB26)),AM26,MAX(AM26-4,4)) -> 8
A27: Leonard | B27: Ciemniecki | C27: 1690 Bay St - Apt 305 | D27: San Francisco | E27: CA | F27: 94123 | G27: 248-925-9102 | H27: lciemniecki@gmail.com | I27: CON | J27: 2025/10/18 | K27: 2 | L27: 1 | M27: =K27*L27 -> 2 | Q27: 251031t163200 | R27: 3 | S27: PGH | T27: 26 | U27: 1 | V27: 23 | W27: 26 | X27: 1 | Y27: 25 | Z27: =1000*(W27-T27)+100*(X27-U27)+(Y27-V27) -> 2 | AA27: 15 | AC27: Y | AE27: =(CODE(MID(H27,1,1))-43)+(CODE(MID(H27,2,1))-43)*80+(CODE(MID(H27,3,1))-43)*80*80+(CODE(MID(H27,4,1))-43)*80*80*80 -> 30097345 | AF27: =OR($S27="BEN",NOT(ISERROR(SEARCH("H",$AB27)))) -> FALSE | AG27: =OR($S27="BRA",NOT(ISERROR(SEARCH("H",$AB27)))) -> FALSE | AH27: =OR($S27="PGH",NOT(ISERROR(SEARCH("H",$AB27)))) -> TRUE | AI27: =OR($S27="LUD",NOT(ISERROR(SEARCH("H",$AB27)))) -> FALSE | AJ27: =DATE(T27+2000,U27,V27) -> 44583 | AK27: =DATE(2000+W27,X27,Y27) -> 44585 | AL27: =VALUE(RIGHT(R27,1)) -> 3 | AM27: =AA27 -> 15 | AN27: =IF(ISERROR(SEARCH("N",$AB27)),AM27,MAX(AM27-4,4)) -> 15
A28: Jake | B28: Parkhurst | C28: 570 Marlestra Rd | D28: Pinole | E28: CA | F28: 94564 | G28: 510-293-1751 | H28: jakeisthesnake@gmail.com | I28: PGH | J28: 2025/10/04 | K28: 2 | L28: 1 | M28: =K28*L28 -> 2 | Q28: 251106t060800 | R28: 1 | S28: PGH | T28: 26 | U28: 2 | V28: 6 | W28: 26 | X28: 2 | Y28: 8 | Z28: =1000*(W28-T28)+100*(X28-U28)+(Y28-V28) -> 2 | AA28: 15 | AC28: Y | AE28: =(CODE(MID(H28,1,1))-43)+(CODE(MID(H28,2,1))-43)*80+(CODE(MID(H28,3,1))-43)*80*80+(CODE(MID(H28,4,1))-43)*80*80*80 -> 30109983 | AF28: =OR($S28="BEN",NOT(ISERROR(SEARCH("H",$AB28)))) -> FALSE | AG28: =OR($S28="BRA",NOT(ISERROR(SEARCH("H",$AB28)))) -> FALSE | AH28: =OR($S28="PGH",NOT(ISERROR(SEARCH("H",$AB28)))) -> TRUE | AI28: =OR($S28="LUD",NOT(ISERROR(SEARCH("H",$AB28)))) -> FALSE | AJ28: =DATE(T28+2000,U28,V28) -> 44597 | AK28: =DATE(2000+W28,X28,Y28) -> 44599 | AL28: =VALUE(RIGHT(R28,1)) -> 1 | AM28: =AA28 -> 15 | AN28: =IF(ISERROR(SEARCH("N",$AB28)),AM28,MAX(AM28-4,4)) -> 15
A29: Tom | B29: Hoke | G29: 804-441-5844 | H29: hoketc11@gmail.com | I29: BEN | J29: 2025/09/19 | K29: 2 | L29: 1 | M29: =K29*L29 -> 2 | Q29: 251029t135900 | R29: 1 | S29: BEN | T29: 26 | U29: 2 | V29: 27 | W29: 26 | X29: 3 | Y29: 1 | Z29: 2 | AA29: 5 | AC29: Y | AE29: =(CODE(MID(H29,1,1))-43)+(CODE(MID(H29,2,1))-43)*80+(CODE(MID(H29,3,1))-43)*80*80+(CODE(MID(H29,4,1))-43)*80*80*80 -> 30111101 | AF29: =OR($S29="BEN",NOT(ISERROR(SEARCH("H",$AB29)))) -> TRUE | AG29: =OR($S29="BRA",NOT(ISERROR(SEARCH("H",$AB29)))) -> FALSE | AH29: =OR($S29="PGH",NOT(ISERROR(SEARCH("H",$AB29)))) -> FALSE | AI29: =OR($S29="LUD",NOT(ISERROR(SEARCH("H",$AB29)))) -> FALSE | AJ29: =DATE(T29+2000,U29,V29) -> 44618 | AK29: =DATE(2000+W29,X29,Y29) -> 44620 | AL29: =VALUE(RIGHT(R29,1)) -> 1 | AM29: =AA29 -> 5 | AN29: =IF(ISERROR(SEARCH("N",$AB29)),AM29,MAX(AM29-4,4)) -> 5
A30: Tom | B30: Hoke | G30: 804-441-5844 | H30: hoketc11@gmail.com | I30: BEN | J30: 2025/09/19 | K30: 2 | L30: 1 | M30: =K30*L30 -> 2 | Q30: 251029t135900 | R30: 1 | S30: BRA | T30: 26 | U30: 3 | V30: 1 | W30: 26 | X30: 3 | Y30: 2 | Z30: =1000*(W30-T30)+100*(X30-U30)+(Y30-V30) -> 1 | AA30: 5 | AC30: Y | AE30: =(CODE(MID(H30,1,1))-43)+(CODE(MID(H30,2,1))-43)*80+(CODE(MID(H30,3,1))-43)*80*80+(CODE(MID(H30,4,1))-43)*80*80*80 -> 30111101 | AF30: =OR($S30="BEN",NOT(ISERROR(SEARCH("H",$AB30)))) -> FALSE | AG30: =OR($S30="BRA",NOT(ISERROR(SEARCH("H",$AB30)))) -> TRUE | AH30: =OR($S30="PGH",NOT(ISERROR(SEARCH("H",$AB30)))) -> FALSE | AI30: =OR($S30="LUD",NOT(ISERROR(SEARCH("H",$AB30)))) -> FALSE | AJ30: =DATE(T30+2000,U30,V30) -> 44620 | AK30: =DATE(2000+W30,X30,Y30) -> 44621 | AL30: =VALUE(RIGHT(R30,1)) -> 1 | AM30: =AA30 -> 5 | AN30: =IF(ISERROR(SEARCH("N",$AB30)),AM30,MAX(AM30-4,4)) -> 5
A31: Luke | B31: Bonham | C31: 1470 25th Ave | D31: San Francisco | E31: CA | F31: 94122 | G31: 714-277-9643 | H31: luke.w.bonham@gmail.com | I31: PGH | J31: 2025/10/04 | K31: 2 | L31: 1 | M31: =K31*L31 -> 2 | Q31: 251103t094500 | R31: S2 | S31: PGH | T31: 26 | U31: 3 | V31: 21 | W31: 26 | X31: 3 | Y31: 22 | Z31: =1000*(W31-T31)+100*(X31-U31)+(Y31-V31) -> 1 | AA31: 4 | AC31: Y | AD31: completed | AE31: =(CODE(MID(H31,1,1))-43)+(CODE(MID(H31,2,1))-43)*80+(CODE(MID(H31,3,1))-43)*80*80+(CODE(MID(H31,4,1))-43)*80*80*80 -> 30111585 | AF31: =OR($S31="BEN",NOT(ISERROR(SEARCH("H",$AB31)))) -> FALSE | AG31: =OR($S31="BRA",NOT(ISERROR(SEARCH("H",$AB31)))) -> FALSE | AH31: =OR($S31="PGH",NOT(ISERROR(SEARCH("H",$AB31)))) -> TRUE | AI31: =OR($S31="LUD",NOT(ISERROR(SEARCH("H",$AB31)))) -> FALSE | AJ31: =DATE(T31+2000,U31,V31) -> 44640 | AK31: =DATE(2000+W31,X31,Y31) -> 44641 | AL31: =VALUE(RIGHT(R31,1)) -> 2 | AM31: =AA31 -> 4 | AN31: =IF(ISERROR(SEARCH("N",$AB31)),AM31,MAX(AM31-4,4)) -> 4
A32: Tyler | B32: Alves | G32: 510-612-1486 | H32: tyler11alves@gmail.com | I32: BEN | J32: 2025/09/19 | K32: 2 | L32: 1 | M32: =K32*L32 -> 2 | Q32: 251103t080300 | R32: S1 | S32: BEN | T32: 26 | U32: 2 | V32: 27 | W32: 26 | X32: 3 | Y32: 1 | Z32: 2 | AA32: 7 | AC32: Y | AD32: completed | AE32: =(CODE(MID(H32,1,1))-43)+(CODE(MID(H32,2,1))-43)*80+(CODE(MID(H32,3,1))-43)*80*80+(CODE(MID(H32,4,1))-43)*80*80*80 -> 30118313 | AF32: =OR($S32="BEN",NOT(ISERROR(SEARCH("H",$AB32)))) -> TRUE | AG32: =OR($S32="BRA",NOT(ISERROR(SEARCH("H",$AB32)))) -> FALSE | AH32: =OR($S32="PGH",NOT(ISERROR(SEARCH("H",$AB32)))) -> FALSE | AI32: =OR($S32="LUD",NOT(ISERROR(SEARCH("H",$AB32)))) -> FALSE | AJ32: =DATE(T32+2000,U32,V32) -> 44618 | AK32: =DATE(2000+W32,X32,Y32) -> 44620 | AL32: =VALUE(RIGHT(R32,1)) -> 1 | AM32: =AA32 -> 7 | AN32: =IF(ISERROR(SEARCH("N",$AB32)),AM32,MAX(AM32-4,4)) -> 7
A33: Danee | B33: Kenyon | C33: 111 N. Rengstorff Ave | D33: Mountain View | E33: CA | F33: 94043 | G33: 760-859-7653 | H33: daneemk@gmail.com | I33: PGH | J33: 2025/08/16 | K33: 2 | L33: 1 | M33: =K33*L33 -> 2 | Q33: 251028t212100 | R33: 1 | S33: PGH | T33: 26 | U33: 4 | V33: 17 | W33: 26 | X33: 4 | Y33: 19 | Z33: =1000*(W33-T33)+100*(X33-U33)+(Y33-V33) -> 2 | AA33: 15 | AB33: N | AC33: Y | AE33: =(CODE(MID(H33,1,1))-43)+(CODE(MID(H33,2,1))-43)*80+(CODE(MID(H33,3,1))-43)*80*80+(CODE(MID(H33,4,1))-43)*80*80*80 -> 30129177 | AF33: =OR($S33="BEN",NOT(ISERROR(SEARCH("H",$AB33)))) -> FALSE | AG33: =OR($S33="BRA",NOT(ISERROR(SEARCH("H",$AB33)))) -> FALSE | AH33: =OR($S33="PGH",NOT(ISERROR(SEARCH("H",$AB33)))) -> TRUE | AI33: =OR($S33="LUD",NOT(ISERROR(SEARCH("H",$AB33)))) -> FALSE | AJ33: =DATE(T33+2000,U33,V33) -> 44667 | AK33: =DATE(2000+W33,X33,Y33) -> 44669 | AL33: =VALUE(RIGHT(R33,1)) -> 1 | AM33: =AA33 -> 15 | AN33: =IF(ISERROR(SEARCH("N",$AB33)),AM33,MAX(AM33-4,4)) -> 11
A34: Noah | B34: Budnick | C34: 2720 Curtis St. | D34: Berkeley | E34: CA | G34: 917-684-7912 | H34: noahbudnick@gmail.com | I34: MUL | J34: 2025/08/23 | K34: 4 | L34: 1 | M34: =K34*L34 -> 4 | Q34: 251029t174600 | R34: 1 | S34: BRA | T34: 26 | U34: 3 | V34: 8 | W34: 26 | X34: 3 | Y34: 10 | Z34: =1000*(W34-T34)+100*(X34-U34)+(Y34-V34) -> 2 | AA34: 5 | AC34: Y | AE34: =(CODE(MID(H34,1,1))-43)+(CODE(MID(H34,2,1))-43)*80+(CODE(MID(H34,3,1))-43)*80*80+(CODE(MID(H34,4,1))-43)*80*80*80 -> 31583107 | AF34: =OR($S34="BEN",NOT(ISERROR(SEARCH("H",$AB34)))) -> FALSE | AG34: =OR($S34="BRA",NOT(ISERROR(SEARCH("H",$AB34)))) -> TRUE | AH34: =OR($S34="PGH",NOT(ISERROR(SEARCH("H",$AB34)))) -> FALSE | AI34: =OR($S34="LUD",NOT(ISERROR(SEARCH("H",$AB34)))) -> FALSE | AJ34: =DATE(T34+2000,U34,V34) -> 44627 | AK34: =DATE(2000+W34,X34,Y34) -> 44629 | AL34: =VALUE(RIGHT(R34,1)) -> 1 | AM34: =AA34 -> 5 | AN34: =IF(ISERROR(SEARCH("N",$AB34)),AM34,MAX(AM34-4,4)) -> 5
A35: Joshua | B35: Foster | C35: 1919 High Meadow Trail | G35: 530-848-8071 | H35: joshuafoster1@gmail.com | I35: LUD | J35: 2025/10/04 | K35: 2 | L35: 1 | M35: =K35*L35 -> 2 | Q35: 251029t215600 | R35: 1 | S35: BEN | T35: 26 | U35: 2 | V35: 5 | W35: 26 | X35: 2 | Y35: 7 | Z35: =1000*(W35-T35)+100*(X35-U35)+(Y35-V35) -> 2 | AA35: 12 | AC35: Y | AE35: =(CODE(MID(H35,1,1))-43)+(CODE(MID(H35,2,1))-43)*80+(CODE(MID(H35,3,1))-43)*80*80+(CODE(MID(H35,4,1))-43)*80*80*80 -> 31698303 | AF35: =OR($S35="BEN",NOT(ISERROR(SEARCH("H",$AB35)))) -> TRUE | AG35: =OR($S35="BRA",NOT(ISERROR(SEARCH("H",$AB35)))) -> FALSE | AH35: =OR($S35="PGH",NOT(ISERROR(SEARCH("H",$AB35)))) -> FALSE | AI35: =OR($S35="LUD",NOT(ISERROR(SEARCH("H",$AB35)))) -> FALSE | AJ35: =DATE(T35+2000,U35,V35) -> 44596 | AK35: =DATE(2000+W35,X35,Y35) -> 44598 | AL35: =VALUE(RIGHT(R35,1)) -> 1 | AM35: =AA35 -> 12 | AN35: =IF(ISERROR(SEARCH("N",$AB35)),AM35,MAX(AM35-4,4)) -> 12
A36: Joshua | B36: Foster | C36: 1919 High Meadow Trail | G36: 530-848-8071 | H36: joshuafoster1@gmail.com | I36: LUD | J36: 2025/10/04 | K36: 2 | L36: 1 | M36: =K36*L36 -> 2 | Q36: 251029t215600 | R36: 1 | S36: BRA | T36: 26 | U36: 2 | V36: 7 | W36: 26 | X36: 2 | Y36: 8 | Z36: =1000*(W36-T36)+100*(X36-U36)+(Y36-V36) -> 1 | AA36: 15 | AC36: Y | AE36: =(CODE(MID(H36,1,1))-43)+(CODE(MID(H36,2,1))-43)*80+(CODE(MID(H36,3,1))-43)*80*80+(CODE(MID(H36,4,1))-43)*80*80*80 -> 31698303 | AF36: =OR($S36="BEN",NOT(ISERROR(SEARCH("H",$AB36)))) -> FALSE | AG36: =OR($S36="BRA",NOT(ISERROR(SEARCH("H",$AB36)))) -> TRUE | AH36: =OR($S36="PGH",NOT(ISERROR(SEARCH("H",$AB36)))) -> FALSE | AI36: =OR($S36="LUD",NOT(ISERROR(SEARCH("H",$AB36)))) -> FALSE | AJ36: =DATE(T36+2000,U36,V36) -> 44598 | AK36: =DATE(2000+W36,X36,Y36) -> 44599 | AL36: =VALUE(RIGHT(R36,1)) -> 1 | AM36: =AA36 -> 15 | AN36: =IF(ISERROR(SEARCH("N",$AB36)),AM36,MAX(AM36-4,4)) -> 15
A37: Craig | B37: Haupt | C37: 1141 Vasquez Ave | D37: Sunnyvale | E37: CA | F37: 94086 | G37: 408-329-3081 | H37: craigmhaupt@gmail.com | I37: PGH | J37: 2025/08/23 | K37: 2 | L37: 1 | M37: =K37*L37 -> 2 | P37: LPC STS | Q37: 251024t022200 | R37: 1 | S37: BEN | T37: 26 | U37: 3 | V37: 14 | W37: 26 | X37: 3 | Y37: 15 | AA37: 4 | AC37: Y | AE37: =(CODE(MID(H37,1,1))-43)+(CODE(MID(H37,2,1))-43)*80+(CODE(MID(H37,3,1))-43)*80*80+(CODE(MID(H37,4,1))-43)*80*80*80 -> 32095336 | AF37: =OR($S37="BEN",NOT(ISERROR(SEARCH("H",$AB37)))) -> TRUE | AG37: =OR($S37="BRA",NOT(ISERROR(SEARCH("H",$AB37)))) -> FALSE | AH37: =OR($S37="PGH",NOT(ISERROR(SEARCH("H",$AB37)))) -> FALSE | AI37: =OR($S37="LUD",NOT(ISERROR(SEARCH("H",$AB37)))) -> FALSE | AJ37: =DATE(T37+2000,U37,V37) -> 44633 | AK37: =DATE(2000+W37,X37,Y37) -> 44634 | AL37: =VALUE(RIGHT(R37,1)) -> 1 | AM37: =AA37 -> 4 | AN37: =IF(ISERROR(SEARCH("N",$AB37)),AM37,MAX(AM37-4,4)) -> 4
A38: Craig | B38: Haupt | C38: 1141 Vasquez Ave | D38: Sunnyvale | E38: CA | F38: 94086 | G38: 408-329-3081 | H38: craigmhaupt@gmail.com | I38: PGH | J38: 2025/08/23 | K38: 2 | L38: 1 | M38: =K38*L38 -> 2 | P38: LPC STS | Q38: 251024t022200 | R38: 1 | S38: BRA | T38: 26 | U38: 3 | V38: 13 | W38: 26 | X38: 3 | Y38: 14 | Z38: =1000*(W38-T38)+100*(X38-U38)+(Y38-V38) -> 1 | AA38: 4 | AC38: Y | AE38: =(CODE(MID(H38,1,1))-43)+(CODE(MID(H38,2,1))-43)*80+(CODE(MID(H38,3,1))-43)*80*80+(CODE(MID(H38,4,1))-43)*80*80*80 -> 32095336 | AF38: =OR($S38="BEN",NOT(ISERROR(SEARCH("H",$AB38)))) -> FALSE | AG38: =OR($S38="BRA",NOT(ISERROR(SEARCH("H",$AB38)))) -> TRUE | AH38: =OR($S38="PGH",NOT(ISERROR(SEARCH("H",$AB38)))) -> FALSE | AI38: =OR($S38="LUD",NOT(ISERROR(SEARCH("H",$AB38)))) -> FALSE | AJ38: =DATE(T38+2000,U38,V38) -> 44632 | AK38: =DATE(2000+W38,X38,Y38) -> 44633 | AL38: =VALUE(RIGHT(R38,1)) -> 1 | AM38: =AA38 -> 4 | AN38: =IF(ISERROR(SEARCH("N",$AB38)),AM38,MAX(AM38-4,4)) -> 4
A39: Daniel | B39: Nelli | C39: 415 Sunny Slope Ave | G39: 704-868-3288 | H39: danielnelli05@gmail.com | I39: CON | J39: 2025/10/18 | K39: 2 | L39: 1 | M39: =K39*L39 -> 2 | Q39: 251103t120300 | R39: S1 | S39: BRA | T39: 26 | U39: 3 | V39: 28 | W39: 26 | X39: 3 | Y39: 30 | Z39: =1000*(W39-T39)+100*(X39-U39)+(Y39-V39) -> 2 | AA39: 15 | AC39: Y | AD39: completed | AE39: =(CODE(MID(H39,1,1))-43)+(CODE(MID(H39,2,1))-43)*80+(CODE(MID(H39,3,1))-43)*80*80+(CODE(MID(H39,4,1))-43)*80*80*80 -> 32177177 | AF39: =OR($S39="BEN",NOT(ISERROR(SEARCH("H",$AB39)))) -> FALSE | AG39: =OR($S39="BRA",NOT(ISERROR(SEARCH("H",$AB39)))) -> TRUE | AH39: =OR($S39="PGH",NOT(ISERROR(SEARCH("H",$AB39)))) -> FALSE | AI39: =OR($S39="LUD",NOT(ISERROR(SEARCH("H",$AB39)))) -> FALSE | AJ39: =DATE(T39+2000,U39,V39) -> 44647 | AK39: =DATE(2000+W39,X39,Y39) -> 44649 | AL39: =VALUE(RIGHT(R39,1)) -> 1 | AM39: =AA39 -> 15 | AN39: =IF(ISERROR(SEARCH("N",$AB39)),AM39,MAX(AM39-4,4)) -> 15
A40: Christie | B40: Ciarlo | C40: 404 Cavar St. | D40: Oakland | E40: CA | F40: 94618 | G40: 407-538-2606 | H40: christie.a.ciarlo@gmail.com | I40: PGH | J40: 2025/10/04 | K40: 2 | L40: 1 | M40: =K40*L40 -> 2 | Q40: 251029t193500 | R40: 1 | S40: BEN | T40: 26 | U40: 2 | V40: 20 | W40: 26 | X40: 2 | Y40: 22 | Z40: =1000*(W40-T40)+100*(X40-U40)+(Y40-V40) -> 2 | AA40: 7 | AB40: D | AC40: Y | AE40: =(CODE(MID(H40,1,1))-43)+(CODE(MID(H40,2,1))-43)*80+(CODE(MID(H40,3,1))-43)*80*80+(CODE(MID(H40,4,1))-43)*80*80*80 -> 32203336 | AF40: =OR($S40="BEN",NOT(ISERROR(SEARCH("H",$AB40)))) -> TRUE | AG40: =OR($S40="BRA",NOT(ISERROR(SEARCH("H",$AB40)))) -> FALSE | AH40: =OR($S40="PGH",NOT(ISERROR(SEARCH("H",$AB40)))) -> FALSE | AI40: =OR($S40="LUD",NOT(ISERROR(SEARCH("H",$AB40)))) -> FALSE | AJ40: =DATE(T40+2000,U40,V40) -> 44611 | AK40: =DATE(2000+W40,X40,Y40) -> 44613 | AL40: =VALUE(RIGHT(R40,1)) -> 1 | AM40: =AA40 -> 7 | AN40: =IF(ISERROR(SEARCH("N",$AB40)),AM40,MAX(AM40-4,4)) -> 7
...

Sheet requestors
A1: Requestor_ID | B1: Email | C1: first_name | D1: last_name | E1: address | F1: city | G1: state | H1: zip | I1: Phone | J1: Comments | K1: Credits | L1: login_code | M1: code_generated_when | N1: Admin | O1: Creation_date | P1: Last_mod_date | Q1: last_failed_login
A2: 1962792 | B2: sam.hoffman99@gmail.com | C2: Sam | D2: Hoffman | F2: Oakland | G2: CA | I2: 720-810-5776 | K2: 2 | N2: FALSE
A3: 1969495 | B3: ben.spielman1223@gmail.com | C3: Benjamin | D3: Spielman | F3: San Francisco | G3: CA | I3: 301-830-0735 | K3: 2 | N3: FALSE
A4: 1975905 | B4: leo.stanislas@gmail.com | C4: Leo | D4: Stanislaus | F4: South Lake Tahoe | G4: CA | I4: 818-930-2028 | K4: 2 | N4: FALSE
A5: 2009181 | B5: hut.coord@yahoo.com | C5: Dick | D5: Simpson | F5: Palo Alto | G5: CA | I5: 650-494-9272 | K5: 14 | N5: TRUE
A6: 3147593 | B6: tk6174@gmail.com | C6: Teddy | D6: Koerner | F6: San Francisco | G6: CA | I6: 303-956-0501 | K6: 2 | N6: FALSE
A7: 3486858 | B7: elk1234567@yahoo.com | C7: Ethan | D7: Kennon | F7: San Francisco | G7: CA | I7: 707-315-9872 | K7: 4 | N7: FALSE
A8: 7212312 | B8: st1993@gmail.com | C8: Scott | D8: Bennett | F8: San Francisco | G8: CA | I8: 650-283-9916 | K8: 2 | N8: FALSE
A9: 27044381 | B9: hal_tompkins@yahoo.com | C9: Hal | D9: Tompkins | F9: Redwood City | G9: CA | I9: 650-400-8351 | K9: 2 | N9: FALSE
A10: 28075512 | B10: sjmac650@gmail.com | C10: Sarah | D10: MacPherson | F10: San Francisco | G10: CA | I10: 650-334-1015 | K10: 2 | N10: FALSE
A11: 28075894 | B11: aomalley17@gmail.com | C11: Anna | D11: O'Malley | F11: San Francisco | G11: CA | I11: 802-540-5101 | K11: 2 | N11: FALSE
A12: 28090137 | B12: d1passmore@yahoo.com | C12: David | D12: Passmore | F12: San Francisco | G12: CA | I12: 650-215-0374 | K12: 2 | N12: FALSE
A13: 28106784 | B13: karadu422@gmail.com | C13: Kate | D13: Radu | F13: Redwood City | G13: CA | I13: 214-402-3918 | K13: 2 | N13: FALSE
... A20: 29098784 | B20: kamcrae@yahoo.com | C20: Katie | D20: McRae | F20: Carson City | G20: NV | I20: 775-220-9792 | K20: 3 | N20: FALSE
A21: 29099095 | B21: bemcrae@yahoo.com | C21: Brian | D21: McRae | I21: 775-230-4338 | K21: 2 | N21: FALSE
A22: 29144226 | B22: mitchell.hannah@gmail.com | C22: Hannah | D22: Mitchell | F22: Oakland | G22: CA | I22: 510-282-2108 | K22: 1 | N22: FALSE
A23: 29176534 | B23: amychen2012@gmail.com | C23: Amy | D23: Chen | F23: San Francisco | G23: CA | I23: 248-321-0848 | K23: 2 | N23: FALSE
A24: 29618303 | B24: jondlittle@gmail.com | C24: Jon | D24: Little | F24: San Francisco | G24: CA | I24: 802-318-8831 | K24: 2 | N24: FALSE
A25: 30097345 | B25: lciemniecki@gmail.com | C25: Leonard | D25: Ciemniecki | F25: San Francisco | G25: CA | I25: 248-925-9102 | K25: 2 | N25: FALSE
A26: 30109983 | B26: jakeisthesnake@gmail.com | C26: Jake | D26: Parkhurst | F26: Pinole | G26: CA | I26: 510-293-1751 | K26: 2 | N26: FALSE
A27: 30111101 | B27: hoketc11@gmail.com | C27: Tom | D27: Hoke | I27: 804-441-5844 | K27: 2 | N27: FALSE
A28: 30111585 | B28: luke.w.bonham@gmail.com | C28: Luke | D28: Bonham | F28: San Francisco | G28: CA | I28: 714-277-9643 | K28: 2 | N28: FALSE
A29: 30118313 | B29: tyler11alves@gmail.com | C29: Tyler | D29: Alves | I29: 510-612-1486 | K29: 2 | N29: FALSE
A30: 30129177 | B30: daneemk@gmail.com | C30: Danee | D30: Kenyon | F30: Mountain View | G30: CA | I30: 760-859-7653 | K30: 2 | N30: FALSE
A31: 31583107 | B31: noahbudnick@gmail.com | C31: Noah | D31: Budnick | F31: Berkeley | G31: CA | I31: 917-684-7912 | K31: 4 | N31: FALSE
A32: 31698303 | B32: joshuafoster1@gmail.com | C32: Joshua | D32: Foster | I32: 530-848-8071 | K32: 2 | N32: FALSE
A33: 32095336 | B33: craigmhaupt@gmail.com | C33: Craig | D33: Haupt | F33: Sunnyvale | G33: CA | I33: 408-329-3081 | K33: 2 | N33: FALSE
A34: 32177177 | B34: danielnelli05@gmail.com | C34: Daniel | D34: Nelli | I34: 704-868-3288 | K34: 2 | N34: FALSE
A35: 32203336 | B35: chrishansenmd@comcast.net | C35: Chris | D35: Hansen | I35: 831-238-0321 | K35: 2 | N35: FALSE
A36: 32222463 | B36: jguild10@gmail.com | C36: Jeff | D36: Guild | I36: 510-708-7701 | K36: 1 | N36: FALSE
A37: 32223105 | B37: louisschueller@gmail.com | C37: Louis | D37: Schueller | F37: Redwood City | G37: CA | I37: 650-743-5226 | K37: 2 | N37: FALSE
A38: 32241505 | B38: lexiarlen@gmail.com | C38: Lexi | D38: Arlen | F38: Menlo Park | G38: CA | I38: 925-309-7104 | K38: 2 | N38: FALSE
A39: 33131427 | B39: nickhunnewell@gmail.com | C39: Nick | D39: Hunnewell | F39: San Francisco | G39: CA | I39: 508-314-8721 | K39: 2 | N39: FALSE
A40: 33131431 | B40: rickards050@gmail.com | C40: Matt | D40: Rickards | F40: Sausalito | G40: CA | I40: 781-910-3917 | K40: 2 | N40: FALSE
A41: 33182627 | B41: nikkival17@gmail.com | C41: Nikki | D41: Valentine | F41: Grass Valley | G41: CA | I41: 619-971-3254 | K41: 2 | N41: FALSE
A42: 33701021 | B42: hill_hiker@hotmail.com | C42: Chris | D42: Oakes | F42: Berkeley | G42: CA | I42: 510-331-6654 | K42: 2 | N42: FALSE
A43: 33701036 | B43: will94574@comcast.net | C43: Will | D43: Smithers | F43: San Francisco | G43: CA | I43: 707-363-0444 | K43: 2 | N43: FALSE
A44: 33701501 | B44: holly.ratcliff@gmail.com | C44: Holly | D44: Lemay | I44: 225-505-0593 | K44: 2 | N44: FALSE
A45: 33721337 | B45: dwolfowitz@gmail.com | C45: David | D45: Wolfowitz | I45: 301-642-6473 | K45: 2 | N45: FALSE
A46: 34226706 | B46: mtnmck@gmail.com | C46: Stephen | D46: McKinley | F46: Berkeley | G46: CA | I46: 781-336-8940 | K46: 2 | N46: FALSE
...

Sheet requests.tsv
A1: Requestor_ID | B1: Benson | C1: Bradley | D1: Grubb | E1: Ludlow | F1: Arrival | G1: Departure | H1: Choice_Number | I1: Spots_ideal | J1: Spots_min | K1: Hut_granted | L1: Spots_granted | M1: Status | N1: Confirmed_How | O1: Creation_date | P1: Last_mod_date
A2: 1962792 | B2: TRUE | C2: TRUE | D2: TRUE | E2: TRUE | F2: 2027-02-06 | G2: 2027-02-07 | H2: 1 | I2: 9 | J2: 9
A3: 1969495 | B3: FALSE | C3: FALSE | D3: TRUE | E3: FALSE | F3: 2027-01-16 | G3: 2027-01-18 | H3: 3 | I3: 6 | J3: 6
A4: 1975905 | B4: TRUE | C4: FALSE | D4: FALSE | E4: FALSE | F4: 2027-03-12 | G4: 2027-03-13 | H4: 1 | I4: 12 | J4: 12
A5: 1975905 | B5: FALSE | C5: TRUE | D5: FALSE | E5: FALSE | F5: 2027-03-13 | G5: 2027-03-14 | H5: 1 | I5: 15 | J5: 15
A6: 2009181 | B6: FALSE | C6: FALSE | D6: TRUE | E6: FALSE | F6: 2027-01-29 | G6: 2027-01-31 | H6: 1 | I6: 15 | J6: 15
A7: 3147593 | B7: FALSE | C7: FALSE | D7: FALSE | E7: TRUE | F7: 2027-03-05 | G7: 2027-03-07 | H7: 4 | I7: 15 | J7: 15
A8: 3486858 | B8: TRUE | C8: FALSE | D8: FALSE | E8: FALSE | F8: 2027-01-15 | G8: 2027-01-18 | H8: 1 | I8: 12 | J8: 8
A9: 7212312 | B9: FALSE | C9: FALSE | D9: TRUE | E9: FALSE | F9: 2027-01-16 | G9: 2027-01-18 | H9: 1 | I9: 6 | J9: 6
A10: 27044381 | B10: FALSE | C10: TRUE | D10: FALSE | E10: FALSE | F10: 2027-01-23 | G10: 2027-01-25 | H10: 1 | I10: 15 | J10: 15
A11: 28075512 | B11: FALSE | C11: TRUE | D11: FALSE | E11: FALSE | F11: 2027-01-14 | G11: 2027-01-17 | H11: 1 | I11: 6 | J11: 4
A12: 28075894 | B12: TRUE | C12: FALSE | D12: FALSE | E12: FALSE | F12: 2027-03-13 | G12: 2027-03-14 | H12: 2 | I12: 7 | J12: 4
A13: 28090137 | B13: FALSE | C13: TRUE | D13: FALSE | E13: FALSE | F13: 2027-03-14 | G13: 2027-03-16 | H13: 1 | I13: 10 | J13: 6
... A91: 40395911 | B91: FALSE | C91: FALSE | D91: TRUE | E91: FALSE | F91: 2027-03-12 | G91: 2027-03-14 | H91: 4 | I91: 15 | J91: 11

Sheet Sheet2

Sheet Sheet3
